Workbook

Sheet result (2)
A1: 2 | B1: 9309750 | C1: -4715500 | D1: -4594450
A2: 3 | B2: 8394600 | C2: -2836550 | D2: -2829750 | E2: -2728600
A3: 4 | B3: 7313800 | C3: -1855450 | D3: -1881950 | E3: -1756500 | F3: -1820300
A4: 5 | B4: 6480250 | C4: -1599700 | D4: -1282500 | E4: -1316050 | F4: -1260600 | G4: -1021900
A5: 6 | B5: 5714250 | C5: -742100 | D5: -1088200 | E5: -883450 | F5: -879600 | G5: -901150 | H5: -1220350
A6: 7 | B6: 5105700 | C6: -499150 | D6: -916550 | E6: -761000 | F6: -818450 | G6: -832500 | H6: -854000 | I6: -424750
A7: 8 | B7: 4385050 | C7: -663950 | D7: -828800 | E7: -378750 | F7: -492800 | G7: -311700 | H7: -643850 | I7: -404850 | J7: -661150
A8: 9 | B8: 3999600 | C8: -160800 | D8: -485750 | E8: -223150 | F8: -672750 | G8: -366700 | H8: -475300 | I8: -730400 | J8: -472600 | K8: -413050
A9: 10 | B9: 3685350 | C9: -5300 | D9: -474550 | E9: -467400 | F9: -411800 | G9: -207700 | H9: 107350 | I9: -643100 | J9: -650950 | K9: -496650 | L9: -436250
A10: 11 | B10: 3684850 | C10: -473650 | D10: -294150 | E10: 81350 | F10: -129350 | G10: -327850 | H10: -390950 | I10: -267050 | J10: -295600 | K10: 167050 | L10: -736600 | M10: -1019150
A11: 12 | B11: 3326800 | C11: -8300 | D11: -333750 | E11: -118700 | F11: -299400 | G11: -445650 | H11: -479250 | I11: -167750 | J11: -88200 | K11: -413250 | L11: -16050 | M11: -716400 | N11: -241300
A12: 13 | B12: 3295200 | C12: -90450 | D12: 7450 | E12: -246800 | F12: -573800 | G12: 51700 | H12: -472500 | I12: -156400 | J12: -583700 | K12: -645850 | L12: -482700 | M12: -492100 | N12: 341700 | O12: 46950

Sheet result
A1: 2 | B1: 9309750 | C1: -4715500 | D1: -4594450
A2: 3 | B2: 8394600 | C2: -2836550 | D2: -2829750 | E2: -2728600
A3: 4 | B3: 7313800 | C3: -1855450 | D3: -1881950 | E3: -1756500 | F3: -1820300
A4: 5 | B4: 6480250 | C4: -1599700 | D4: -1282500 | E4: -1316050 | F4: -1260600 | G4: -1021900
A5: 6 | B5: 5714250 | C5: -742100 | D5: -1088200 | E5: -883450 | F5: -879600 | G5: -901150 | H5: -1220350
A6: 7 | B6: 5105700 | C6: -499150 | D6: -916550 | E6: -761000 | F6: -818450 | G6: -832500 | H6: -854000 | I6: -424750
A7: 8 | B7: 4385050 | C7: -663950 | D7: -828800 | E7: -378750 | F7: -492800 | G7: -311700 | H7: -643850 | I7: -404850 | J7: -661150
A8: 9 | B8: 3999600 | C8: -160800 | D8: -485750 | E8: -223150 | F8: -672750 | G8: -366700 | H8: -475300 | I8: -730400 | J8: -472600 | K8: -413050
A9: 10 | B9: 3685350 | C9: -5300 | D9: -474550 | E9: -467400 | F9: -411800 | G9: -207700 | H9: 107350 | I9: -643100 | J9: -650950 | K9: -496650 | L9: -436250
A10: 11 | B10: 3684850 | C10: -473650 | D10: -294150 | E10: 81350 | F10: -129350 | G10: -327850 | H10: -390950 | I10: -267050 | J10: -295600 | K10: 167050 | L10: -736600 | M10: -1019150
A11: 12 | B11: 3326800 | C11: -8300 | D11: -333750 | E11: -118700 | F11: -299400 | G11: -445650 | H11: -479250 | I11: -167750 | J11: -88200 | K11: -413250 | L11: -16050 | M11: -716400 | N11: -241300
A12: 13 | B12: 3295200 | C12: -90450 | D12: 7450 | E12: -246800 | F12: -573800 | G12: 51700 | H12: -472500 | I12: -156400 | J12: -583700 | K12: -645850 | L12: -482700 | M12: -492100 | N12: 341700 | O12: 46950
A13: 14 | B13: 2868300 | C13: 146350 | D13: 71700 | E13: 1150 | F13: -338200 | G13: -94550 | H13: -306850 | I13: -457850 | J13: 9700 | K13: -412150 | L13: 338550 | M13: -421150 | N13: -669150 | O13: -580100 | P13: -157150
A14: 15 | B14: 2836400 | C14: -430250 | D14: -302100 | E14: 61050 | F14: -268250 | G14: -481200 | H14: -340950 | I14: 469100 | J14: 702250 | K14: -148900 | L14: -479300 | M14: -738050 | N14: -493900 | O14: 252750 | P14: -372150 | Q14: -268000
A15: 16 | B15: 3010050 | C15: -427600 | D15: 66350 | E15: -244250 | F15: -396550 | G15: -235200 | H15: -210350 | I15: 190800 | J15: -102400 | K15: 20800 | L15: -92350 | M15: -231150 | N15: 319950 | O15: -628600 | P15: -487850 | Q15: -579000 | R15: 25750
A16: 17 | B16: 2802950 | C16: -471850 | D16: -869250 | E16: -210250 | F16: -99000 | G16: -81900 | H16: -654250 | I16: 381250 | J16: -107550 | K16: -34600 | L16: 684150 | M16: -132050 | N16: 34600 | O16: -258850 | P16: 8400 | Q16: -641250 | R16: -187950 | S16: -164300
A17: 18 | B17: 3184550 | C17: 13650 | D17: -257450 | E17: -57000 | F17: 62100 | G17: 339800 | H17: -178200 | I17: -317100 | J17: 366250 | K17: -340200 | L17: -278600 | M17: -561950 | N17: -408900 | O17: -280650 | P17: -480450 | Q17: 26900 | R17: -102750 | S17: -114650 | T17: -617150
A18: 19 | B18: 2755250 | C18: 612450 | D18: 74700 | E18: -438450 | F18: -377100 | G18: -58450 | H18: -146650 | I18: 154250 | J18: 337200 | K18: -634000 | L18: -812850 | M18: -111950 | N18: -346350 | O18: 126050 | P18: -371150 | Q18: 257850 | R18: -846950 | S18: 165050 | T18: 61000 | U18: -401800
A19: 20 | B19: 3321950 | C19: -552900 | D19: -508900 | E19: -52600 | F19: -198100 | G19: 24800 | H19: -186600 | I19: -800950 | J19: -544800 | K19: -224050 | L19: 285050 | M19: 336550 | N19: -580450 | O19: -131350 | P19: -85950 | Q19: 95950 | R19: -490800 | S19: 344750 | T19: 169100 | U19: 96200 | V19: -318900
A20: 21 | B20: 3188500 | C20: -584100 | D20: 522850 | E20: -200 | F20: 521550 | G20: -264050 | H20: -232300 | I20: 378900 | J20: -150 | K20: -38150 | L20: -51200 | M20: -952450 | N20: -250300 | O20: -57200 | P20: -846050 | Q20: -117500 | R20: 131450 | S20: -247900 | T20: -283950 | U20: -311850 | V20: 30850 | W20: -538850
A21: 22 | B21: 3313250 | C21: -656150 | D21: -63400 | E21: -372250 | F21: -191950 | G21: -227950 | H21: -813800 | I21: -647650 | J21: 67300 | K21: 868850 | L21: -815650 | M21: 172450 | N21: -443950 | O21: -44800 | P21: 32900 | Q21: -123650 | R21: -229300 | S21: -138600 | T21: 258800 | U21: -52550 | V21: 210950 | W21: 249100 | X21: -354150
A22: 23 | B22: 2999350 | C22: -144600 | D22: -442300 | E22: 224000 | F22: 98450 | G22: 151100 | H22: 157450 | I22: 281550 | J22: -482200 | K22: -434100 | L22: 161800 | M22: -354350 | N22: -106250 | O22: -41800 | P22: 185850 | Q22: -864700 | R22: -416950 | S22: 82850 | T22: -184900 | U22: -350100 | V22: 31050 | W22: 540350 | X22: -285500 | Y22: -808350
A23: 24 | B23: 3053600 | C23: -324650 | D23: -317000 | E23: 247600 | F23: 98150 | G23: -347650 | H23: -549000 | I23: 217450 | J23: 10400 | K23: -186500 | L23: -326950 | M23: 73800 | N23: -57600 | O23: -95100 | P23: -183050 | Q23: -111050 | R23: -425350 | S23: 307850 | T23: -306850 | U23: -823350 | V23: 417100 | W23: -162750 | X23: -94350 | Y23: 187800 | Z23: -304950
A24: 25 | B24: 3119050 | C24: 265450 | D24: -184450 | E24: -30050 | F24: -268000 | G24: -310900 | H24: -1087250 | I24: -263200 | J24: 71650 | K24: 59850 | L24: -567850 | M24: -151800 | N24: 42950 | O24: -199450 | P24: 761950 | Q24: -107700 | R24: -181200 | S24: 299450 | T24: 87700 | U24: 53950 | V24: 119650 | W24: -165550 | X24: -300750 | Y24: -316900 | Z24: -255400 | AA24: -493700
A25: 26 | B25: 3029150 | C25: 199750 | D25: -133600 | E25: 207150 | F25: -396750 | G25: -175600 | H25: -232450 | I25: 236250 | J25: -724650 | K25: -500800 | L25: -312600 | M25: 514800 | N25: -168900 | O25: -521300 | P25: -531000 | Q25: -136250 | R25: -248100 | S25: 83900 | T25: -410450 | U25: -272750 | V25: -675450 | W25: 663750 | X25: -240050 | Y25: -142250 | Z25: -146850 | AA25: 739050 | AB25: 293400
A26: 27 | B26: 3217350 | C26: 73350 | D26: -818950 | E26: -219900 | F26: 140850 | G26: 81400 | H26: -919000 | I26: 133150 | J26: 500900 | K26: -589050 | L26: -105900 | M26: -47600 | N26: -751650 | O26: -184950 | P26: 493350 | Q26: 293500 | R26: -167200 | S26: -33850 | T26: -348800 | U26: -368400 | V26: -550750 | W26: 162250 | X26: 548550 | Y26: 223600 | Z26: -107050 | AA26: -279550 | AB26: -630500 | AC26: 252150
A27: 28 | B27: 3171900 | C27: 58500 | D27: -296450 | E27: -375000 | F27: -662400 | G27: 218500 | H27: -840450 | I27: 123600 | J27: -81350 | K27: 61650 | L27: -523050 | M27: 32150 | N27: -486250 | O27: -316400 | P27: 504750 | Q27: -291700 | R27: 46850 | S27: -139100 | T27: 3750 | U27: -476750 | V27: -457950 | W27: 237800 | X27: -291150 | Y27: 783350 | Z27: -178300 | AA27: 147800 | AB27: -115900 | AC27: 111900 | AD27: 26900
A28: 29 | B28: 2658650 | C28: 374450 | D28: 278200 | E28: 74250 | F28: -580200 | G28: -641750 | H28: 90850 | I28: -115050 | J28: -750550 | K28: 493400 | L28: -268900 | M28: -105650 | N28: -392000 | O28: -80050 | P28: 257800 | Q28: -26900 | R28: -81100 | S28: -1055800 | T28: -189800 | U28: 146850 | V28: -77900 | W28: 98650 | X28: -888450 | Y28: 181350 | Z28: 161250 | AA28: 107250 | AB28: -680950 | AC28: 44750 | AD28: 552100 | AE28: 412350
A29: 30 | B29: 2970100 | C29: 522650 | D29: -399650 | E29: -466100 | F29: -350700 | G29: -422750 | H29: 218800 | I29: -92550 | J29: 219450 | K29: -115550 | L29: -174150 | M29: -490100 | N29: 173350 | O29: -589850 | P29: 343850 | Q29: 191000 | R29: 297650 | S29: 872750 | T29: -8050 | U29: -744200 | V29: 89000 | W29: -23400 | X29: -315600 | Y29: -23450 | Z29: -510850 | AA29: -645400 | AB29: -245050 | AC29: -137250 | AD29: -192300 | AE29: -72500 | AF29: 117850
A30: 31 | B30: 2955350 | C30: -265050 | D30: -540800 | E30: -37350 | F30: 571550 | G30: 403450 | H30: -781500 | I30: 413600 | J30: -525400 | K30: -801700 | L30: -783750 | M30: -710450 | N30: -26350 | O30: -205750 | P30: -229200 | Q30: 569350 | R30: 119100 | S30: -191100 | T30: 73050 | U30: -411900 | V30: -206650 | W30: -19350 | X30: -216050 | Y30: 566650 | Z30: -129650 | AA30: 317600 | AB30: 385100 | AC30: 522250 | AD30: -855500 | AE30: -13550 | AF30: 465950 | AG30: -415050
A31: 32 | B31: 2491350 | C31: 222000 | D31: 340050 | E31: 272650 | F31: 236200 | G31: 374250 | H31: 108000 | I31: 221900 | J31: -476750 | K31: 131550 | L31: -21200 | M31: -286650 | N31: -428800 | O31: -303450 | P31: -135350 | Q31: -501100 | R31: 68350 | S31: -225150 | T31: 33250 | U31: -185850 | V31: -635250 | W31: -21100 | X31: -90500 | Y31: -451350 | Z31: -531000 | AA31: -611350 | AB31: -349950 | AC31: -29750 | AD31: -237900 | AE31: -153450 | AF31: 593900 | AG31: 54900 | AH31: 524350
A32: 33 | B32: 2918750 | C32: -190400 | D32: 757350 | E32: 376600 | F32: 377050 | G32: -132400 | H32: 259200 | I32: -423850 | J32: -335150 | K32: 28950 | L32: -447950 | M32: -684900 | N32: 22300 | O32: -928600 | P32: -448300 | Q32: 153950 | R32: 169100 | S32: 484350 | T32: 171450 | U32: 377550 | V32: -341200 | W32: 524050 | X32: -163150 | Y32: 446000 | Z32: -486400 | AA32: -586300 | AB32: -715800 | AC32: -549250 | AD32: 91050 | AE32: -432150 | AF32: -91500 | AG32: -272850 | AH32: 516950 | AI32: -447800
A33: 34 | B33: 3003500 | C33: -65350 | D33: -423800 | E33: -406450 | F33: -71400 | G33: 542900 | H33: -213400 | I33: 287300 | J33: 157450 | K33: -425650 | L33: -733800 | M33: 9700 | N33: -287200 | O33: -513500 | P33: -40450 | Q33: -476000 | R33: 396300 | S33: -110050 | T33: -508550 | U33: 320950 | V33: 4650 | W33: -407400 | X33: 418500 | Y33: 79750 | Z33: 475400 | AA33: -418200 | AB33: -80400 | AC33: 361000 | AD33: 77300 | AE33: -214900 | AF33: -96250 | AG33: -29550 | AH33: -499500 | AI33: -223500 | AJ33: 107200
A34: 35 | B34: 2959000 | C34: 550750 | D34: 64400 | E34: 60900 | F34: -569700 | G34: -269150 | H34: -655800 | I34: 245150 | J34: 182950 | K34: -97200 | L34: 484200 | M34: 469050 | N34: 622050 | O34: 751300 | P34: 7000 | Q34: -652650 | R34: -33400 | S34: 161400 | T34: 427000 | U34: -686000 | V34: 554450 | W34: -647550 | X34: -445000 | Y34: -1164100 | Z34: -514500 | AA34: -522500 | AB34: -144750 | AC34: 161500 | AD34: -118450 | AE34: -502650 | AF34: -979850 | AG34: 605600 | AH34: -195050 | AI34: -604450 | AJ34: 141100 | AK34: 351450
A35: 36 | B35: 3149150 | C35: 402100 | D35: -237300 | E35: 419000 | F35: -201650 | G35: -523550 | H35: -520550 | I35: -305800 | J35: 193200 | K35: -213300 | L35: 85550 | M35: -261650 | N35: -101300 | O35: -1295200 | P35: -565700 | Q35: 346200 | R35: 151350 | S35: 137350 | T35: -430650 | U35: -3400 | V35: -146250 | W35: 250200 | X35: -321900 | Y35: 253650 | Z35: 217550 | AA35: 203400 | AB35: -40350 | AC35: 527600 | AD35: -97400 | AE35: 696700 | AF35: -375350 | AG35: -227900 | AH35: -557150 | AI35: -619500 | AJ35: -88500 | AK35: -52800 | AL35: 150550
A36: 37 | B36: 3152250 | C36: -509250 | D36: 267100 | E36: -85000 | F36: 348450 | G36: -319500 | H36: -173950 | I36: -124150 | J36: -926150 | K36: -513800 | L36: 431000 | M36: -79700 | N36: 148450 | O36: -263600 | P36: 173450 | Q36: -70350 | R36: 181750 | S36: 141850 | T36: -148450 | U36: -358050 | V36: 659700 | W36: 91200 | X36: 42800 | Y36: 959900 | Z36: -42300 | AA36: -837300 | AB36: -1068800 | AC36: 73600 | AD36: -399150 | AE36: 285400 | AF36: 548850 | AG36: -13050 | AH36: -412850 | AI36: -548800 | AJ36: -702350 | AK36: -396600 | AL36: -88500 | AM36: 572200
A37: 38 | B37: 2759400 | C37: -132600 | D37: -323050 | E37: -42100 | F37: -331250 | G37: -601250 | H37: -418500 | I37: -444000 | J37: -177200 | K37: 262200 | L37: -22500 | M37: -581550 | N37: 975600 | O37: -222350 | P37: -250350 | Q37: -403650 | R37: 835200 | S37: -266250 | T37: 144150 | U37: 174750 | V37: -13100 | W37: 359750 | X37: 798500 | Y37: -224000 | Z37: 131400 | AA37: -655000 | AB37: -511300 | AC37: -158150 | AD37: -53200 | AE37: -427450 | AF37: -493950 | AG37: -586700 | AH37: 192800 | AI37: 43250 | AJ37: 193800 | AK37: -547200 | AL37: 919900 | AM37: -93100 | AN37: 185250
A38: 39 | B38: 3367850 | C38: -117850 | D38: 231600 | E38: -110750 | F38: -13600 | G38: -65400 | H38: -895300 | I38: -460950 | J38: 87900 | K38: -192150 | L38: 31350 | M38: 208800 | N38: -539450 | O38: 204300 | P38: -243400 | Q38: -53950 | R38: 148450 | S38: -796250 | T38: -704800 | U38: -220400 | V38: -84950 | W38: 34550 | X38: 1084050 | Y38: 1054250 | Z38: 821900 | AA38: -333750 | AB38: 129000 | AC38: 709050 | AD38: -838600 | AE38: -85950 | AF38: -351550 | AG38: -718350 | AH38: 102950 | AI38: -8800 | AJ38: -93550 | AK38: 583800 | AL38: -276600 | AM38: 294000 | AN38: -844400 | AO38: -1046950
A39: 40 | B39: 2361400 | C39: 110700 | D39: 23650 | E39: -555750 | F39: 64750 | G39: -161650 | H39: 20750 | I39: -589350 | J39: -34100 | K39: 996050 | L39: -248350 | M39: 604800 | N39: -1448450 | O39: -26750 | P39: 9900 | Q39: -287800 | R39: 320550 | S39: 232550 | T39: -363400 | U39: -34100 | V39: -70950 | W39: -117100 | X39: -788100 | Y39: -27050 | Z39: 912350 | AA39: -141000 | AB39: -893350 | AC39: 681250 | AD39: -643550 | AE39: -22200 | AF39: 85000 | AG39: 85250 | AH39: -215050 | AI39: 348150 | AJ39: 731950 | AK39: 62100 | AL39: -133150 | AM39: -331650 | AN39: 126200 | AO39: -363150 | AP39: -285350
A40: 41 | B40: 2500900 | C40: 2000 | D40: 475750 | E40: -579500 | F40: 336250 | G40: -286000 | H40: 607800 | I40: -276200 | J40: 13300 | K40: -73150 | L40: -629550 | M40: 641350 | N40: -533450 | O40: 153650 | P40: -347200 | Q40: 927000 | R40: -221600 | S40: -735850 | T40: -110750 | U40: -201350 | V40: 553900 | W40: 1438550 | X40: 386350 | Y40: 204050 | Z40: 761000 | AA40: -1094900 | AB40: -447250 | AC40: 554750 | AD40: 42950 | AE40: -658700 | AF40: -1107350 | AG40: 32500 | AH40: -641400 | AI40: -993200 | AJ40: -278750 | AK40: -243750 | AL40: 505750 | AM40: -837800 | AN40: 1053000 | AO40: -247850 | AP40: -36600 | AQ40: -612750
...

Sheet 統計
A1: 2 | B1: =AVERAGEIF(result!$C1:$AWZ1, "<>0") / 100000 -> -46.54975 | D1: {=A1:A1300} -> 2 | E1: =AVERAGEIF(result!B1, "<>0") / 100000 -> 93.0975
A2: 3 | B2: =AVERAGEIF(result!$C2:$AWZ2, "<>0") / 100000 -> -27.983 | D2: 3 | E2: =AVERAGEIF(result!B2, "<>0") / 100000 -> 83.946
A3: 4 | B3: =AVERAGEIF(result!$C3:$AWZ3, "<>0") / 100000 -> -18.2855 | D3: 4 | E3: =AVERAGEIF(result!B3, "<>0") / 100000 -> 73.138
A4: 5 | B4: =AVERAGEIF(result!$C4:$AWZ4, "<>0") / 100000 -> -12.9615 | D4: 5 | E4: =AVERAGEIF(result!B4, "<>0") / 100000 -> 64.8025
A5: 6 | B5: =AVERAGEIF(result!$C5:$AWZ5, "<>0") / 100000 -> -9.52475 | D5: 6 | E5: =AVERAGEIF(result!B5, "<>0") / 100000 -> 57.1425
A6: 7 | B6: =AVERAGEIF(result!$C6:$AWZ6, "<>0") / 100000 -> -7.2948571 | D6: 7 | E6: =AVERAGEIF(result!B6, "<>0") / 100000 -> 51.057
A7: 8 | B7: =AVERAGEIF(result!$C7:$AWZ7, "<>0") / 100000 -> -5.4823125 | D7: 8 | E7: =AVERAGEIF(result!B7, "<>0") / 100000 -> 43.8505
A8: 9 | B8: =AVERAGEIF(result!$C8:$AWZ8, "<>0") / 100000 -> -4.445 | D8: 9 | E8: =AVERAGEIF(result!B8, "<>0") / 100000 -> 39.996
A9: 10 | B9: =AVERAGEIF(result!$C9:$AWZ9, "<>0") / 100000 -> -3.68635 | D9: 10 | E9: =AVERAGEIF(result!B9, "<>0") / 100000 -> 36.8535
A10: 11 | B10: =AVERAGEIF(result!$C10:$AWZ10, "<>0") / 100000 -> -3.3508636 | D10: 11 | E10: =AVERAGEIF(result!B10, "<>0") / 100000 -> 36.8485
A11: 12 | B11: =AVERAGEIF(result!$C11:$AWZ11, "<>0") / 100000 -> -2.7733333 | D11: 12 | E11: =AVERAGEIF(result!B11, "<>0") / 100000 -> 33.268
A12: 13 | B12: =AVERAGEIF(result!$C12:$AWZ12, "<>0") / 100000 -> -2.5357692 | D12: 13 | E12: =AVERAGEIF(result!B12, "<>0") / 100000 -> 32.952
A13: 14 | B13: =AVERAGEIF(result!$C13:$AWZ13, "<>0") / 100000 -> -2.0497857 | D13: 14 | E13: =AVERAGEIF(result!B13, "<>0") / 100000 -> 28.683
... A1299: 1300 | B1299: =AVERAGEIF(result!$C1299:$AWZ1299, "<>0") / 100000 -> #DIV/0! | D1299: 1300 | E1299: =AVERAGEIF(result!B1299, "<>0") / 100000 -> #DIV/0!
D1300: 0 | E1300: =AVERAGEIF(result!B1300, "<>0") / 100000 -> #DIV/0!
